Workbook
Name COREISADDONS: [1]LIST!#REF!
Name COREISADDONS: [1]LIST!#REF!
Name COREISADDONS: [1]LIST!#REF!
Name Currency: '[2]Named Ranges'!$A$2:$A$18
Name Currency: '[2]Named Ranges'!$A$2:$A$18
Name Currency: '[2]Named Ranges'!$A$2:$A$18
Name Currency: '[2]Named Ranges'!$A$2:$A$18
Name Currency: '[3]Named Ranges'!$A$2:$A$18
Name NewParts: 'New Parts'!$D$3:$D$26
Name Parts: '[4]Upgrade Parts Future_K_v4.0'!$H$3:$H$498
Name Parts: '[5]Upgrade Parts Future_K_v4.0'!$H$3:$H$498
Name Parts: '[5]Upgrade Parts Future_K_v4.0'!$H$3:$H$498
Name Parts: '[5]Upgrade Parts Future_K_v4.0'!$H$3:$H$498
Name Parts: '[6]Upgrade Parts Future_K_v4.1'!$H$3:$H$498
Name Parts: 'Upgrade Parts Future_K_v5.4'!$H$3:$H$498
Name Parts: 'Upgrade Parts Future_K_v6.0'!$H$3:$H$498
Name Parts: 'Upgrade Parts Future_K_v6.4'!$H$3:$H$498
Name Parts: 'Upgrade Parts Future_K_v4.1'!$H$3:$H$498
Name Route_to_Market: '[2]Named Ranges'!$E$2:$E$3
Name Route_to_Market: '[2]Named Ranges'!$E$2:$E$3
Name Route_to_Market: '[2]Named Ranges'!$E$2:$E$3
Name Route_to_Market: '[2]Named Ranges'!$E$2:$E$3
Name Route_to_Market: '[3]Named Ranges'!$E$2:$E$3
Name rsvp: '[2]Named Ranges'!$C$2:$C$11
Name rsvp: '[2]Named Ranges'!$C$2:$C$11
Name rsvp: '[2]Named Ranges'!$C$2:$C$11
Name rsvp: '[2]Named Ranges'!$C$2:$C$11
Name rsvp: '[3]Named Ranges'!$C$2:$C$11
Name usertype: '[6]New Parts'!$D$37:$D$44
Name usertype: 'New Parts'!$D$37:$D$47
Name usertypepoints: '[6]New Parts'!$D$37:$E$44
Name usertypepoints: 'New Parts'!$D$37:$E$47

Sheet Instructions
C3: MAS New Deal/Upgrade/Trade-up Request Forms
D6: Instructions All fields in the forms are required to be filled out for consideration of an upgrade or trade-up. Go to the Details tab to enter the bid details. You will also need to fill in information regarding the parts to be trading up and/or upgrading to. Follow the below steps to complete the process of raising the request: i. Complete the DETAILS tab: Please ensure all required fields are filled out. ii. Complete the Calculator Tab with the current entitlement being requested to upgrade.
A28: NOTE: Pricing and Packaging Guides located on Seismic under Maximo Application Suite/Pricing Plan - https://ibm.seismic.com/Link/Content/DCV7TR4HYCgUaD2mrkzrxzAQ | U28: Last updated 10/28/2022

Sheet Details - New Deal
A2: New Deal Request Form *Required Fields
B3: Please complete all questions
A5: Requester Info
A7: *Requester Name
A8: *Requester Email
A10: Customer Info
A12: *Customer Name
A13: *Site Number
A14: *IBM Customer Number
A15: Is this a GTS/GBS contract? | C15: *These are Not eligible - Answer should be NO
A16: Is this an ESA contract? | C16: * If yes, ESA exception approval required
A17: Is this a new customer / non upgradable
A18: Sales Connect Opportunity Number
A19: Is the customer on a Hotlist or the IWL? YES / NO / Don't Know (from SQO)
A20: Is the customer under an audit? YES / NO / Don't Know (from SQO)
A21: Currency
A23: Further Details of the Deal
A25: Expected New Contract Duration? (minimum 12 months)
A26: Projected Close Date | B26: DD/MM/YYYY
A27: Projected Deal Size
A28: Will the deal be financed? with IGF? Y/N
A29: Will special terms be required, if yes, explain?
A31: MAS REQUEST

Sheet New Deal Calculator
B1: MAS New Deal calculator
B3: Customer Name | C3: License Type | D3: Quantity | E3: Line Item Description | F3: AppPoints Required | G3: Total Required AppPoints
F4: =IF(ISBLANK(C4),"",VLOOKUP($C4,'New Parts'!D37:E54,2,FALSE)) | G4: =IFERROR(F4*D4,"")
F5: =IF(ISBLANK(C5),"",VLOOKUP($C5,'New Parts'!D37:E54,2,FALSE)) | G5: =IFERROR(F5*D5,"")
F6: =IF(ISBLANK(C6),"",VLOOKUP($C6,'New Parts'!D37:E54,2,FALSE)) | G6: =IFERROR(F6*D6,"")
F7: =IF(ISBLANK(C7),"",VLOOKUP($C7,'New Parts'!D37:E54,2,FALSE)) | G7: =IFERROR(F7*D7,"")
F8: =IF(ISBLANK(C8),"",VLOOKUP($C8,'New Parts'!D37:E54,2,FALSE)) | G8: =IFERROR(F8*D8,"")
F9: =IF(ISBLANK(C9),"",VLOOKUP($C9,'New Parts'!D37:E54,2,FALSE)) | G9: =IFERROR(F9*D9,"")
F10: =IF(ISBLANK(C10),"",VLOOKUP($C10,'New Parts'!D37:E54,2,FALSE)) | G10: =IFERROR(F10*D10,"")
F11: =IF(ISBLANK(C11),"",VLOOKUP($C11,'New Parts'!D37:E54,2,FALSE)) | G11: =IFERROR(F11*D11,"")
F12: =IF(ISBLANK(C12),"",VLOOKUP($C12,'New Parts'!D37:E54,2,FALSE)) | G12: =IFERROR(F12*D12,"")
F13: =IF(ISBLANK(C13),"",VLOOKUP($C13,'New Parts'!D37:E54,2,FALSE)) | G13: =IFERROR(F13*D13,"")
F14: =IF(ISBLANK(C14),"",VLOOKUP($C14,'New Parts'!D37:E54,2,FALSE)) | G14: =IFERROR(F14*D14,"")
F15: =IF(ISBLANK(C15),"",VLOOKUP($C15,'New Parts'!D37:E54,2,FALSE)) | G15: =IFERROR(F15*D15,"")
F16: =IF(ISBLANK(C16),"",VLOOKUP($C16,'New Parts'!D37:E54,2,FALSE)) | G16: =IFERROR(F16*D16,"")
F17: =IF(ISBLANK(C17),"",VLOOKUP($C17,'New Parts'!D37:E54,2,FALSE)) | G17: =IFERROR(F17*D17,"")
F18: =IF(ISBLANK(C18),"",VLOOKUP($C18,'New Parts'!D37:E54,2,FALSE)) | G18: =IFERROR(F18*D18,"")
F19: =IF(ISBLANK(C19),"",VLOOKUP($C19,'New Parts'!D37:E54,2,FALSE)) | G19: =IFERROR(F19*D19,"")
F20: =IF(ISBLANK(C20),"",VLOOKUP($C20,'New Parts'!D37:E54,2,FALSE)) | G20: =IFERROR(F20*D20,"")
F21: =IF(ISBLANK(C21),"",VLOOKUP($C21,'New Parts'!D37:E54,2,FALSE)) | G21: =IFERROR(F21*D21,"")
F22: =IF(ISBLANK(C22),"",VLOOKUP($C22,'New Parts'!D37:E54,2,FALSE)) | G22: =IFERROR(F22*D22,"")
B23: Total | D23: =SUM(D4:D22) -> 0 | G23: =SUM(G4:G22) -> 0
B24: NOTE:
B25: At least 1 Admin Premium User must be added to a New Deal bid.

Sheet  New Deal STL Pricing
A1: IBM CONFIDENTIAL
A2: Note : Please fill in the green highlighted cells only
A3: SQO billing needs to be "Upfront" for the term of the deal. IGF financing can be leveraged for yearly billing.
A4: Contact MAS project office for pricing guidance /non standard pricing
A6: MAS STL Pricing (USD) | H6: Import Managed Services pricing from Managed services Calculator
A7: MAS Points needed | B7: Price /Point (USD) | C7: MAS Yearly List Price | D7: Discount | E7: Net Price/Year | H7: MAS STL + Managed Services
B8: 82 | C8: =A8*B8*12 -> 0 | D8: 0 | E8: =C8*(1-D8) -> 0
D10: Year 2 | E10: =E8 -> 0
D11: Year 3 | E11: =E10 -> 0
D12: Year 4 | E12: =E11 -> 0
D13: Year 5 | E13: =E12 -> 0 | F13: MAS STL Bookable
D14: TOTAL 3yr | E14: =E8+E10+E11 -> 0 | F14: =E14*0.57 -> 0 | H14: =SUM(H8:H11) -> 0
D15: TOTAL 5yr | E15: =E14+E12+E13 -> 0 | F15: =E15*0.44 -> 0 | H15: =H14+H12+H13 -> 0

Sheet Details - Upgrade Parts
B2: Upgrade Request Form *Required Fields
B3: Please complete all questions
B5: Requester Info
B7: *Requester Name
B8: *Requester Email
B10: S&S Renewal Rep Info
B12: *S&S Renewal Rep Name
B13: *S&S Renewal Rep Email | E13: http://dimond.naasc.ibm.com:9080/DimondWebApp
B15: Customer Info
B17: *Customer Name
B18: *Site Number
B19: *IBM Customer Number | E19: Was the existing entitlement purchased direct through IBM or partner (channel)?
B20: Is this a GTS/GBS contract? *These are Not eligible - Answer should be NO | E20: Will the upgrade be purchased direct through IBM or partner (channel)?
B21: Is this an ESA contract? * If yes, ESA exception approval required | E21: Was the Channel Inentive code BP-Led for prior purchases
B22: Sales Connect Opportunity Number | E22: *Note: Flips from direct to channel not allowed if Incentive Code was Direct or Co-Led. See Play 7.14 for instructions if the Channel Incentive code was BP-Led. Exception approval needed by WW S&S; Add'l Uplifts will apply
B23: When is the opportunity expected to close? | C23: DD/MM/YYYY
B24: Currency | E24: Is the customer on a Hotlist or the IWL? YES / NO / Don't Know (from SQO)
E25: Is the customer under an audit? YES / NO / Don't Know (from SQO)
B26: Further Details of the Deal | E26: Is there existing S&S on these products? If yes, fill out the S&S section below
B28: Have you analyzed your customer's entire entitlement for all eligible parts for upgrade?
B29: When is the S&S renewal date? | C29: DD/MM/YYYY
B30: *Note: Upgrade should happen at the client's renewal date. There is no credit on exiting S&S for an early upgrade | F30: Contract type holding entitlements for upgrade
B31: Are you requesting ALL active licenses for upgrade? | F31: Has the dealmaker been engaged?
B32: Please provide justification for partial upgrade (only required if "No" to above) | F32: Dealmaker Name
B33: Is there a request to upgrade expired SS? | F33: Original contract start date | G33: DD/MM/YYYY
B34: Have you engaged your S&S Renewal Rep for a reach back quote to bring the entitlements current on S&S? | F34: Contract end date | G34: DD/MM/YYYY
B35: (only required if "Yes" to above) | F35: Year to year S&S growth rate on existing agreement (ex: Flat, 3%, 5% etc)
F36: If the contract is NOT expiring, is this part of an amendment or termination of the contract? Please select one option.
F37: Have all parts for upgrade been declared to IBM with reports / Proof of Entitlement?
F38: When is declaration expected? (only required if "No" to above)
F39: *Note - Mid-term upgrade is NOT allowed without an amendment to an ELA or termination of IULA
B41: Expected New Contract Duration? (minimum 12 months)
B42: Projected Close Date | C42: DD/MM/YYYY
B43: Projected Deal Size | D43: ww
B44: Will the deal be financed? with RBD? Y/N
B45: Will special terms be required, if yes, explain?
B46: Is customer a service provider? If yes, do you need SP Contract Variant? (Must include DM), migration period for S&S?
B50: MAS REQUEST

Sheet Upgrade Parts Calculator
B2: Maximo upgradable parts calculator for MAS
B4: Customer name | C4: Part # | D4: Part Description | E4: Current Customer Entitlement | F4: Upgrade AppPoints / Health RVU divide by 10 | G4: AppPoints for Upgrade | H4: Total Upgradable AppPoints
B5: xxxx | D5: =IF(ISBLANK(C5),"",(VLOOKUP($C5,'Upgrade Parts Future_K_v6.4'!$H$3:$M$528,2,FALSE))) | F5: =IF(ISBLANK(E5), "", IF(AND(VLOOKUP(C5,'Upgrade Parts Future_K_v6.0'!$H$3:$K$528,4,FALSE)="Resource Value Unit", E5 < 10), 1, IF(VLOOKUP(C5,'Upgrade Parts Future_K_v6.0'!$H$3:$K$528,4,FALSE)="Resource Value Unit", E5/10, E5 ) ) ) | G5: =IF(ISBLANK(E5),"",(VLOOKUP($C5,'Upgrade Parts Future_K_v6.4'!$H$3:$M$528,5,FALSE))) | H5: =IF(ISBLANK(E5),"",ROUNDUP((F5*G5),0))
D6: =IF(ISBLANK(C6),"",(VLOOKUP($C6,'Upgrade Parts Future_K_v6.4'!$H$3:$M$528,2,FALSE))) | F6: =IF(ISBLANK(E6), "", IF(AND(VLOOKUP(C6,'Upgrade Parts Future_K_v6.0'!$H$3:$K$528,4,FALSE)="Resource Value Unit", E6 < 10), 1, IF(VLOOKUP(C6,'Upgrade Parts Future_K_v6.0'!$H$3:$K$528,4,FALSE)="Resource Value Unit", E6/10, E6 ) ) ) | G6: =IF(ISBLANK(E6),"",(VLOOKUP($C6,'Upgrade Parts Future_K_v6.4'!$H$3:$M$528,5,FALSE))) | H6: =IF(ISBLANK(E6),"",ROUNDUP((F6*G6),0))
D7: =IF(ISBLANK(C7),"",(VLOOKUP($C7,'Upgrade Parts Future_K_v6.4'!$H$3:$M$528,2,FALSE))) | F7: =IF(ISBLANK(E7), "", IF(AND(VLOOKUP(C7,'Upgrade Parts Future_K_v6.0'!$H$3:$K$528,4,FALSE)="Resource Value Unit", E7 < 10), 1, IF(VLOOKUP(C7,'Upgrade Parts Future_K_v6.0'!$H$3:$K$528,4,FALSE)="Resource Value Unit", E7/10, E7 ) ) ) | G7: =IF(ISBLANK(E7),"",(VLOOKUP($C7,'Upgrade Parts Future_K_v6.4'!$H$3:$M$528,5,FALSE))) | H7: =IF(ISBLANK(E7),"",ROUNDUP((F7*G7),0))
D8: =IF(ISBLANK(C8),"",(VLOOKUP($C8,'Upgrade Parts Future_K_v6.4'!$H$3:$M$528,2,FALSE))) | F8: =IF(ISBLANK(E8), "", IF(AND(VLOOKUP(C8,'Upgrade Parts Future_K_v6.0'!$H$3:$K$528,4,FALSE)="Resource Value Unit", E8 < 10), 1, IF(VLOOKUP(C8,'Upgrade Parts Future_K_v6.0'!$H$3:$K$528,4,FALSE)="Resource Value Unit", E8/10, E8 ) ) ) | G8: =IF(ISBLANK(E8),"",(VLOOKUP($C8,'Upgrade Parts Future_K_v6.4'!$H$3:$M$528,5,FALSE))) | H8: =IF(ISBLANK(E8),"",ROUNDUP((F8*G8),0))
D9: =IF(ISBLANK(C9),"",(VLOOKUP($C9,'Upgrade Parts Future_K_v6.4'!$H$3:$M$528,2,FALSE))) | F9: =IF(ISBLANK(E9), "", IF(AND(VLOOKUP(C9,'Upgrade Parts Future_K_v6.0'!$H$3:$K$528,4,FALSE)="Resource Value Unit", E9 < 10), 1, IF(VLOOKUP(C9,'Upgrade Parts Future_K_v6.0'!$H$3:$K$528,4,FALSE)="Resource Value Unit", E9/10, E9 ) ) ) | G9: =IF(ISBLANK(E9),"",(VLOOKUP($C9,'Upgrade Parts Future_K_v6.4'!$H$3:$M$528,5,FALSE))) | H9: =IF(ISBLANK(E9),"",ROUNDUP((F9*G9),0))
D10: =IF(ISBLANK(C10),"",(VLOOKUP($C10,'Upgrade Parts Future_K_v6.4'!$H$3:$M$528,2,FALSE))) | F10: =IF(ISBLANK(E10), "", IF(AND(VLOOKUP(C10,'Upgrade Parts Future_K_v6.0'!$H$3:$K$528,4,FALSE)="Resource Value Unit", E10 < 10), 1, IF(VLOOKUP(C10,'Upgrade Parts Future_K_v6.0'!$H$3:$K$528,4,FALSE)="Resource Value Unit", E10/10, E10 ) ) ) | G10: =IF(ISBLANK(E10),"",(VLOOKUP($C10,'Upgrade Parts Future_K_v6.4'!$H$3:$M$528,5,FALSE))) | H10: =IF(ISBLANK(E10),"",ROUNDUP((F10*G10),0))
D11: =IF(ISBLANK(C11),"",(VLOOKUP($C11,'Upgrade Parts Future_K_v6.4'!$H$3:$M$528,2,FALSE))) | F11: =IF(ISBLANK(E11), "", IF(AND(VLOOKUP(C11,'Upgrade Parts Future_K_v6.0'!$H$3:$K$528,4,FALSE)="Resource Value Unit", E11 < 10), 1, IF(VLOOKUP(C11,'Upgrade Parts Future_K_v6.0'!$H$3:$K$528,4,FALSE)="Resource Value Unit", E11/10, E11 ) ) ) | G11: =IF(ISBLANK(E11),"",(VLOOKUP($C11,'Upgrade Parts Future_K_v6.4'!$H$3:$M$528,5,FALSE))) | H11: =IF(ISBLANK(E11),"",ROUNDUP((F11*G11),0))
D12: =IF(ISBLANK(C12),"",(VLOOKUP($C12,'Upgrade Parts Future_K_v6.4'!$H$3:$M$528,2,FALSE))) | F12: =IF(ISBLANK(E12), "", IF(AND(VLOOKUP(C12,'Upgrade Parts Future_K_v6.0'!$H$3:$K$528,4,FALSE)="Resource Value Unit", E12 < 10), 1, IF(VLOOKUP(C12,'Upgrade Parts Future_K_v6.0'!$H$3:$K$528,4,FALSE)="Resource Value Unit", E12/10, E12 ) ) ) | G12: =IF(ISBLANK(E12),"",(VLOOKUP($C12,'Upgrade Parts Future_K_v6.4'!$H$3:$M$528,5,FALSE))) | H12: =IF(ISBLANK(E12),"",ROUNDUP((F12*G12),0))
D13: =IF(ISBLANK(C13),"",(VLOOKUP($C13,'Upgrade Parts Future_K_v6.4'!$H$3:$M$528,2,FALSE))) | F13: =IF(ISBLANK(E13), "", IF(AND(VLOOKUP(C13,'Upgrade Parts Future_K_v6.0'!$H$3:$K$528,4,FALSE)="Resource Value Unit", E13 < 10), 1, IF(VLOOKUP(C13,'Upgrade Parts Future_K_v6.0'!$H$3:$K$528,4,FALSE)="Resource Value Unit", E13/10, E13 ) ) ) | G13: =IF(ISBLANK(E13),"",(VLOOKUP($C13,'Upgrade Parts Future_K_v6.4'!$H$3:$M$528,5,FALSE))) | H13: =IF(ISBLANK(E13),"",ROUNDUP((F13*G13),0))
D14: =IF(ISBLANK(C14),"",(VLOOKUP($C14,'Upgrade Parts Future_K_v6.4'!$H$3:$M$528,2,FALSE))) | F14: =IF(ISBLANK(E14), "", IF(AND(VLOOKUP(C14,'Upgrade Parts Future_K_v6.0'!$H$3:$K$528,4,FALSE)="Resource Value Unit", E14 < 10), 1, IF(VLOOKUP(C14,'Upgrade Parts Future_K_v6.0'!$H$3:$K$528,4,FALSE)="Resource Value Unit", E14/10, E14 ) ) ) | G14: =IF(ISBLANK(E14),"",(VLOOKUP($C14,'Upgrade Parts Future_K_v6.4'!$H$3:$M$528,5,FALSE))) | H14: =IF(ISBLANK(E14),"",ROUNDUP((F14*G14),0))
D15: =IF(ISBLANK(C15),"",(VLOOKUP($C15,'Upgrade Parts Future_K_v6.4'!$H$3:$M$528,2,FALSE))) | F15: =IF(ISBLANK(E15), "", IF(AND(VLOOKUP(C15,'Upgrade Parts Future_K_v6.0'!$H$3:$K$528,4,FALSE)="Resource Value Unit", E15 < 10), 1, IF(VLOOKUP(C15,'Upgrade Parts Future_K_v6.0'!$H$3:$K$528,4,FALSE)="Resource Value Unit", E15/10, E15 ) ) ) | G15: =IF(ISBLANK(E15),"",(VLOOKUP($C15,'Upgrade Parts Future_K_v6.4'!$H$3:$M$528,5,FALSE))) | H15: =IF(ISBLANK(E15),"",ROUNDUP((F15*G15),0))
D16: =IF(ISBLANK(C16),"",(VLOOKUP($C16,'Upgrade Parts Future_K_v6.4'!$H$3:$M$528,2,FALSE))) | F16: =IF(ISBLANK(E16), "", IF(AND(VLOOKUP(C16,'Upgrade Parts Future_K_v6.0'!$H$3:$K$528,4,FALSE)="Resource Value Unit", E16 < 10), 1, IF(VLOOKUP(C16,'Upgrade Parts Future_K_v6.0'!$H$3:$K$528,4,FALSE)="Resource Value Unit", E16/10, E16 ) ) ) | G16: =IF(ISBLANK(E16),"",(VLOOKUP($C16,'Upgrade Parts Future_K_v6.4'!$H$3:$M$528,5,FALSE))) | H16: =IF(ISBLANK(E16),"",ROUNDUP((F16*G16),0))
D17: =IF(ISBLANK(C17),"",(VLOOKUP($C17,'Upgrade Parts Future_K_v6.4'!$H$3:$M$528,2,FALSE))) | F17: =IF(ISBLANK(E17), "", IF(AND(VLOOKUP(C17,'Upgrade Parts Future_K_v6.0'!$H$3:$K$528,4,FALSE)="Resource Value Unit", E17 < 10), 1, IF(VLOOKUP(C17,'Upgrade Parts Future_K_v6.0'!$H$3:$K$528,4,FALSE)="Resource Value Unit", E17/10, E17 ) ) ) | G17: =IF(ISBLANK(E17),"",(VLOOKUP($C17,'Upgrade Parts Future_K_v6.4'!$H$3:$M$528,5,FALSE))) | H17: =IF(ISBLANK(E17),"",ROUNDUP((F17*G17),0))
... D35: =IF(ISBLANK(C35),"",(VLOOKUP($C35,'Upgrade Parts Future_K_v6.4'!$H$3:$M$528,2,FALSE))) | F35: =IF(ISBLANK(E35), "", IF(AND(VLOOKUP(C35,'Upgrade Parts Future_K_v6.0'!$H$3:$K$528,4,FALSE)="Resource Value Unit", E35 < 10), 1, IF(VLOOKUP(C35,'Upgrade Parts Future_K_v6.0'!$H$3:$K$528,4,FALSE)="Resource Value Unit", E35/10, E35 ) ) ) | G35: =IF(ISBLANK(E35),"",(VLOOKUP($C35,'Upgrade Parts Future_K_v6.4'!$H$3:$M$528,5,FALSE))) | H35: =IF(ISBLANK(E35),"",ROUNDUP((F35*G35),0))
B36: Total | E36: =SUM(E5:E35) -> 0 | H36: =MROUND(SUM(H5:H35),5) -> 0

Sheet Subscription Upgrade Pricing
A1: IBM Internal and Business Partner Use Only | G1: Input Cells
A2: Note : Please fill in the green highlighted cells only | G2: Formula Cells
A3: MAS upgrade pricing needs to be uplifted a minimum of 35% (Could be higher but not lower than 35%)
A4: SQO billing needs to be "Upfront" for the term of the deal if >$2M. IGF financing can be leveraged for yearly payments
A5: Reminder : Attach the S&S checklist (See Play 7.14); Make sure you say Yes in the SQO bid that a Play is being used (see Play 7.14)
A6: Contact MAS project office for pricing guidance /non standard pricing; Consult the 7.14 Play for Uplifts on RTM shifts and guidance
A8: Is this an FCT client (y/n) | B8: NO | C8: (If NO, leave cell "A11" blank )
A10: UPFRONT PAYMENTS at 3% - MAS STL Pricing (USD) / Update to local currency if ouside US and note currency being used
A11: LPP on FCT 2022 (Provided by the FCT S&S rep) | B11: LPP on PA uplifted 0% from FCT LPP (Provided by S&S rep) | C11: MAS Uplift of 35%* | D11: MAS Points needed (qty for the Upgrade part number D28B5LL) | E11: Uprade Price /Point (Local Currency) | F11: Upgrade Yearly List Price | G11: Discount | H11: Net Price/Year | K11: Import Managed Services pricing from Managed services Calculator
C12: =B12*1.35 -> 0 | E12: 36 | F12: =D12*E12*12 -> 0 | G12: =1-(H12/F12) -> #DIV/0! | H12: =C12 -> 0 | K12: MAS STL + Managed Services
A14: *Adjust this rate for Play approved RTM shifts if approved. | F14: =+F12 -> 0 | G14: Year 2 | H14: =H12 *1.03 -> 0
F15: =+F14 -> 0 | G15: Year 3 | H15: =H14 *1.03 -> 0
F16: =+F15 -> 0 | G16: Year 4 | H16: =H15 *1.03 -> 0
F17: =+F16 -> 0 | G17: Year 5 | H17: =H16 *1.03 -> 0 | I17: MAS STL Bookable
F18: =F12+F14+F15 -> 0 | G18: TOTAL 3yr | H18: =H12+H14+H15 -> 0 | I18: =H18*0.15 -> 0 | K18: =SUM(K13:K15) -> 0
F19: =F18+F16+F17 -> 0 | G19: TOTAL 5yr | H19: =H18+H16+H17 -> 0 | I19: =H19*0.11 -> 0 | K19: =K18+K16+K17 -> 0
A29: ANNUAL PAYMENTS at 5% - MAS STL Pricing (USD) / Update to local currency if ouside US and note currency being used
A30: LPP on FCT 2022 (Provided by the FCT S&S rep) | B30: LPP on PA uplifted 0% from FCT LPP (Provided by S&S rep) | C30: MAS Uplift of 35%* | D30: MAS Points needed (qty for the Upgrade part number D28B5LL) | E30: Uprade Price /Point (Local Currency) | F30: Upgrade Yearly List Price | G30: Discount | H30: Net Price/Year | K30: Import Managed Services pricing from Managed services Calculator
C31: =B31*1.35 -> 0 | E31: 36 | F31: =D31*E31*12 -> 0 | G31: =1-(H31/F31) -> #DIV/0! | H31: =C31 -> 0 | K31: MAS STL + Managed Services
A33: *Adjust this rate for Play approved RTM shifts if approved. | F33: =+F31 -> 0 | G33: Year 2 | H33: =H31 * 1.05 -> 0
F34: =+F33 -> 0 | G34: Year 3 | H34: =H33 * 1.05 -> 0
F35: =+F34 -> 0 | G35: Year 4 | H35: =H34 * 1.05 -> 0
F36: =+F35 -> 0 | G36: Year 5 | H36: =H35 * 1.05 -> 0 | I36: MAS STL Bookable
F37: =F31+F33+F34 -> 0 | G37: TOTAL 3yr | H37: =H31+H33+H34 -> 0 | I37: =H37*0.15 -> 0 | K37: =SUM(K32:K34) -> 0
F38: =F37+F35+F36 -> 0 | G38: TOTAL 5yr | H38: =H37+H35+H36 -> 0 | I38: =H38*0.11 -> 0 | K38: =K37+K35+K36 -> 0
A40: RTM Shift Scenario outside of the Play approved scenarios or when Geo rates are not available in the Play:
A42: MAS STL Pricing (USD) / Update to local currency if ouside US and note currency being used
A43: LPP on FCT 2020 (Provided by the FCT S&S rep) | B43: LPP on PA uplifted 0% from FCT LPP (Provided by S&S rep) | C43: MAS Uplift of 35%* | D43: MAS Points needed (qty for the Upgrade part number D28B5LL) | E43: Uprade Price /Point (Local Currency) | F43: Upgrade Yearly List Price | G43: Discount | H43: Net Price/Year | I43: Add'l Incentive Uplifts if required (modify the % based on Lamar Murphy input) | J43: Min Price required w RTM Shift | K43: Discount
B44: 100 | C44: =B44*1.35 -> 135 | D44: 100 | E44: 36 | F44: =D44*E44*12 -> 43200 | G44: =1-(H44/F44) -> 0.996875 | H44: =C44 -> 135 | I44: 0.12 | J44: =H44*(1+I44) -> 151.2 | K44: =1-J44/F44 -> 0.9965
F46: =+F44 -> 43200 | G46: Year 2 | H46: =H44 -> 135
F47: =+F46 -> 43200 | G47: Year 3 | H47: =H46 -> 135
A48: * Adjust this rate to what John Dewey/Carlos Belak tell you; Also add the add'l incentive from Lamar Murphy. | F48: =+F47 -> 43200 | G48: Year 4 | H48: =H47 -> 135
F49: =+F48 -> 43200 | G49: Year 5 | H49: =H48 -> 135 | I49: MAS STL Bookable
F50: =F44+F46+F47 -> 129600 | G50: TOTAL 3yr | H50: =H44+H46+H47 -> 405 | I50: =H50*0.15 -> 60.75
F51: =F50+F48+F49 -> 216000 | G51: TOTAL 5yr | H51: =H50+H48+H49 -> 675 | I51: =H51*0.11 -> 74.25

Sheet Details - Trade-up Parts 
B2: Trade-up Request Form *Required Fields
B3: Please complete all questions
B5: Requester Info
B7: *Requester Name
B8: *Requester Email
B10: S&S Renewal Rep Info
B12: *S&S Renewal Rep Name
B13: *S&S Renewal Rep Email | E13: http://dimond.naasc.ibm.com:9080/DimondWebApp
B15: Customer Info
B17: *Customer Name
B18: *Site Number
B19: *IBM Customer Number | E19: Was the existing entitlement purchased direct through IBM or partner (channel)?
B20: Is this a GTS/GBS contract? *These are Not eligible - Answer should be NO | E20: Will the upgrade be purchased direct through IBM or partner (channel)?
B21: Is this an ESA contract? | E21: *Note: Flips from direct to channel not allowed. Exception approval needed by WW S&S
B22: Sales Connect Opportunity Number
B23: When is the opportunity expected to close? | C23: DD/MM/YYYY | E23: Is the customer on a Hotlist or the IWL? YES / NO / Don't Know (from SQO)
B24: Currency | E24: Is the customer under an audit? YES / NO / Don't Know (from SQO)
E25: Is there existing S&S on these products? If yes, fill out the S&S section below
B26: Further Details of the Deal
B28: Have you analyzed your customer's entire entitlement for all eligible parts for upgrade?
B29: When is the S&S renewal date? | C29: DD/MM/YYYY | F29: Contract type holding entitlements for upgrade
B30: *Note: Upgrade should happen at the client's renewal date. There is no credit on exiting S&S for an early upgrade | F30: Has the dealmaker been engaged?
B31: Are you requesting ALL active licenses for upgrade? | F31: Dealmaker Name
B32: Please provide justification for partial upgrade (only required if "No" to above) | F32: Original contract start date | G32: DD/MM/YYYY
B33: Is there a request to upgrade expired SS? | F33: Contract end date | G33: DD/MM/YYYY
B34: Have you engaged your S&S Renewal Rep for a reach back quote to bring the entitlements current on S&S? | F34: Year to year S&S growth rate on existing agreement (ex: Flat, 3%, 5% etc)
B35: (only required if "Yes" to above) | F35: If the contract is NOT expiring, is this part of an amendment or termination of the contract? Please select one option.
F36: Have all parts for upgrade been declared to IBM with reports / Proof of Entitlement?
F37: When is declaration expected? (only required if "No" to above)
F38: *Note - Mid-term upgrade is NOT allowed without an amendment to an ELA or termination of IULA
B41: MAS REQUEST

Sheet Trade-up Parts Calculator
B2: Maximo trade-up parts calculator for MAS
B4: Customer name | C4: Part # | D4: Part Description | E4: Current Customer Entitlement | F4: Authorized User to Concurrent User Normalization by Dividing by 3, Health RVU by 10 | G4: AppPoints for Upgrade | H4: Total Upgradable AppPoints
B5: xxxx | D5: =IF(ISBLANK(C5),"",(VLOOKUP($C5,'Upgrade Parts Future_K_v6.4'!$H$3:$M$528,2,FALSE))) | F5: =IF(ISBLANK(E5), "", IF(AND(VLOOKUP(C5,'Upgrade Parts Future_K_v6.4'!$H$3:$K$528,4,FALSE)="Resource Value Unit", E5 < 10), 1, IF(VLOOKUP(C5,'Upgrade Parts Future_K_v6.4'!$H$3:$K$528,4,FALSE)="Resource Value Unit", E5/10, E5 ) ) ) | G5: =IF(ISBLANK(E5),"",(VLOOKUP($C5,'Upgrade Parts Future_K_v6.4'!$H$3:$M$528,5,FALSE))) | H5: =IF(ISBLANK(E5),"",ROUNDUP((F5*G5),0))
D6: =IF(ISBLANK(C6),"",(VLOOKUP($C6,'Upgrade Parts Future_K_v6.4'!$H$3:$M$528,2,FALSE))) | F6: =IF(ISBLANK(E6), "", IF(AND(VLOOKUP(C6,'Upgrade Parts Future_K_v6.4'!$H$3:$K$528,4,FALSE)="Resource Value Unit", E6 < 10), 1, IF(VLOOKUP(C6,'Upgrade Parts Future_K_v6.4'!$H$3:$K$528,4,FALSE)="Resource Value Unit", E6/10, E6 ) ) ) | G6: =IF(ISBLANK(E6),"",(VLOOKUP($C6,'Upgrade Parts Future_K_v6.4'!$H$3:$M$528,5,FALSE))) | H6: =IF(ISBLANK(E6),"",ROUNDUP((F6*G6),0))
D7: =IF(ISBLANK(C7),"",(VLOOKUP($C7,'Upgrade Parts Future_K_v6.4'!$H$3:$M$528,2,FALSE))) | F7: =IF(ISBLANK(E7), "", IF(AND(VLOOKUP(C7,'Upgrade Parts Future_K_v6.4'!$H$3:$K$528,4,FALSE)="Resource Value Unit", E7 < 10), 1, IF(VLOOKUP(C7,'Upgrade Parts Future_K_v6.4'!$H$3:$K$528,4,FALSE)="Resource Value Unit", E7/10, E7 ) ) ) | G7: =IF(ISBLANK(E7),"",(VLOOKUP($C7,'Upgrade Parts Future_K_v6.4'!$H$3:$M$528,5,FALSE))) | H7: =IF(ISBLANK(E7),"",ROUNDUP((F7*G7),0))
D8: =IF(ISBLANK(C8),"",(VLOOKUP($C8,'Upgrade Parts Future_K_v6.4'!$H$3:$M$528,2,FALSE))) | F8: =IF(ISBLANK(E8), "", IF(AND(VLOOKUP(C8,'Upgrade Parts Future_K_v6.4'!$H$3:$K$528,4,FALSE)="Resource Value Unit", E8 < 10), 1, IF(VLOOKUP(C8,'Upgrade Parts Future_K_v6.4'!$H$3:$K$528,4,FALSE)="Resource Value Unit", E8/10, E8 ) ) ) | G8: =IF(ISBLANK(E8),"",(VLOOKUP($C8,'Upgrade Parts Future_K_v6.4'!$H$3:$M$528,5,FALSE))) | H8: =IF(ISBLANK(E8),"",ROUNDUP((F8*G8),0))
D9: =IF(ISBLANK(C9),"",(VLOOKUP($C9,'Upgrade Parts Future_K_v6.4'!$H$3:$M$528,2,FALSE))) | F9: =IF(ISBLANK(E9), "", IF(AND(VLOOKUP(C9,'Upgrade Parts Future_K_v6.4'!$H$3:$K$528,4,FALSE)="Resource Value Unit", E9 < 10), 1, IF(VLOOKUP(C9,'Upgrade Parts Future_K_v6.4'!$H$3:$K$528,4,FALSE)="Resource Value Unit", E9/10, E9 ) ) ) | G9: =IF(ISBLANK(E9),"",(VLOOKUP($C9,'Upgrade Parts Future_K_v6.4'!$H$3:$M$528,5,FALSE))) | H9: =IF(ISBLANK(E9),"",ROUNDUP((F9*G9),0))
D10: =IF(ISBLANK(C10),"",(VLOOKUP($C10,'Upgrade Parts Future_K_v6.4'!$H$3:$M$528,2,FALSE))) | F10: =IF(ISBLANK(E10), "", IF(AND(VLOOKUP(C10,'Upgrade Parts Future_K_v6.4'!$H$3:$K$528,4,FALSE)="Resource Value Unit", E10 < 10), 1, IF(VLOOKUP(C10,'Upgrade Parts Future_K_v6.4'!$H$3:$K$528,4,FALSE)="Resource Value Unit", E10/10, E10 ) ) ) | G10: =IF(ISBLANK(E10),"",(VLOOKUP($C10,'Upgrade Parts Future_K_v6.4'!$H$3:$M$528,5,FALSE))) | H10: =IF(ISBLANK(E10),"",ROUNDUP((F10*G10),0))
D11: =IF(ISBLANK(C11),"",(VLOOKUP($C11,'Upgrade Parts Future_K_v6.4'!$H$3:$M$528,2,FALSE))) | F11: =IF(ISBLANK(E11), "", IF(AND(VLOOKUP(C11,'Upgrade Parts Future_K_v6.4'!$H$3:$K$528,4,FALSE)="Resource Value Unit", E11 < 10), 1, IF(VLOOKUP(C11,'Upgrade Parts Future_K_v6.4'!$H$3:$K$528,4,FALSE)="Resource Value Unit", E11/10, E11 ) ) ) | G11: =IF(ISBLANK(E11),"",(VLOOKUP($C11,'Upgrade Parts Future_K_v6.4'!$H$3:$M$528,5,FALSE))) | H11: =IF(ISBLANK(E11),"",ROUNDUP((F11*G11),0))
D12: =IF(ISBLANK(C12),"",(VLOOKUP($C12,'Upgrade Parts Future_K_v6.4'!$H$3:$M$528,2,FALSE))) | F12: =IF(ISBLANK(E12), "", IF(AND(VLOOKUP(C12,'Upgrade Parts Future_K_v6.4'!$H$3:$K$528,4,FALSE)="Resource Value Unit", E12 < 10), 1, IF(VLOOKUP(C12,'Upgrade Parts Future_K_v6.4'!$H$3:$K$528,4,FALSE)="Resource Value Unit", E12/10, E12 ) ) ) | G12: =IF(ISBLANK(E12),"",(VLOOKUP($C12,'Upgrade Parts Future_K_v6.4'!$H$3:$M$528,5,FALSE))) | H12: =IF(ISBLANK(E12),"",ROUNDUP((F12*G12),0))
D13: =IF(ISBLANK(C13),"",(VLOOKUP($C13,'Upgrade Parts Future_K_v6.4'!$H$3:$M$528,2,FALSE))) | F13: =IF(ISBLANK(E13), "", IF(AND(VLOOKUP(C13,'Upgrade Parts Future_K_v6.4'!$H$3:$K$528,4,FALSE)="Resource Value Unit", E13 < 10), 1, IF(VLOOKUP(C13,'Upgrade Parts Future_K_v6.4'!$H$3:$K$528,4,FALSE)="Resource Value Unit", E13/10, E13 ) ) ) | G13: =IF(ISBLANK(E13),"",(VLOOKUP($C13,'Upgrade Parts Future_K_v6.4'!$H$3:$M$528,5,FALSE))) | H13: =IF(ISBLANK(E13),"",ROUNDUP((F13*G13),0))
D14: =IF(ISBLANK(C14),"",(VLOOKUP($C14,'Upgrade Parts Future_K_v6.4'!$H$3:$M$528,2,FALSE))) | F14: =IF(ISBLANK(E14), "", IF(AND(VLOOKUP(C14,'Upgrade Parts Future_K_v6.4'!$H$3:$K$528,4,FALSE)="Resource Value Unit", E14 < 10), 1, IF(VLOOKUP(C14,'Upgrade Parts Future_K_v6.4'!$H$3:$K$528,4,FALSE)="Resource Value Unit", E14/10, E14 ) ) ) | G14: =IF(ISBLANK(E14),"",(VLOOKUP($C14,'Upgrade Parts Future_K_v6.4'!$H$3:$M$528,5,FALSE))) | H14: =IF(ISBLANK(E14),"",ROUNDUP((F14*G14),0))
D15: =IF(ISBLANK(C15),"",(VLOOKUP($C15,'Upgrade Parts Future_K_v6.4'!$H$3:$M$528,2,FALSE))) | F15: =IF(ISBLANK(E15), "", IF(AND(VLOOKUP(C15,'Upgrade Parts Future_K_v6.4'!$H$3:$K$528,4,FALSE)="Resource Value Unit", E15 < 10), 1, IF(VLOOKUP(C15,'Upgrade Parts Future_K_v6.4'!$H$3:$K$528,4,FALSE)="Resource Value Unit", E15/10, E15 ) ) ) | G15: =IF(ISBLANK(E15),"",(VLOOKUP($C15,'Upgrade Parts Future_K_v6.4'!$H$3:$M$528,5,FALSE))) | H15: =IF(ISBLANK(E15),"",ROUNDUP((F15*G15),0))
D16: =IF(ISBLANK(C16),"",(VLOOKUP($C16,'Upgrade Parts Future_K_v6.4'!$H$3:$M$528,2,FALSE))) | F16: =IF(ISBLANK(E16), "", IF(AND(VLOOKUP(C16,'Upgrade Parts Future_K_v6.4'!$H$3:$K$528,4,FALSE)="Resource Value Unit", E16 < 10), 1, IF(VLOOKUP(C16,'Upgrade Parts Future_K_v6.4'!$H$3:$K$528,4,FALSE)="Resource Value Unit", E16/10, E16 ) ) ) | G16: =IF(ISBLANK(E16),"",(VLOOKUP($C16,'Upgrade Parts Future_K_v6.4'!$H$3:$M$528,5,FALSE))) | H16: =IF(ISBLANK(E16),"",ROUNDUP((F16*G16),0))
D17: =IF(ISBLANK(C17),"",(VLOOKUP($C17,'Upgrade Parts Future_K_v6.4'!$H$3:$M$528,2,FALSE))) | F17: =IF(ISBLANK(E17), "", IF(AND(VLOOKUP(C17,'Upgrade Parts Future_K_v6.4'!$H$3:$K$528,4,FALSE)="Resource Value Unit", E17 < 10), 1, IF(VLOOKUP(C17,'Upgrade Parts Future_K_v6.4'!$H$3:$K$528,4,FALSE)="Resource Value Unit", E17/10, E17 ) ) ) | G17: =IF(ISBLANK(E17),"",(VLOOKUP($C17,'Upgrade Parts Future_K_v6.4'!$H$3:$M$528,5,FALSE))) | H17: =IF(ISBLANK(E17),"",ROUNDUP((F17*G17),0))
... D35: =IF(ISBLANK(C35),"",(VLOOKUP($C35,'Upgrade Parts Future_K_v6.4'!$H$3:$M$528,2,FALSE))) | F35: =IF(ISBLANK(E35), "", IF(AND(VLOOKUP(C35,'Upgrade Parts Future_K_v6.4'!$H$3:$K$528,4,FALSE)="Resource Value Unit", E35 < 10), 1, IF(VLOOKUP(C35,'Upgrade Parts Future_K_v6.4'!$H$3:$K$528,4,FALSE)="Resource Value Unit", E35/10, E35 ) ) ) | G35: =IF(ISBLANK(E35),"",(VLOOKUP($C35,'Upgrade Parts Future_K_v6.4'!$H$3:$M$528,5,FALSE))) | H35: =IF(ISBLANK(E35),"",ROUNDUP((F35*G35),0))
B36: Total | E36: =SUM(E5:E35) -> 0 | H36: =MROUND(SUM(H5:H35),5) -> 0

Sheet Perpetual Trade-up Pricing
A1: IBM Internal and Business Partner Use Only | H1: Input Cells
A2: Note : Please fill in the green highlighted cells only using local currency | H2: Formula Cells
A3: MAS Perpetual Trade-up pricing needs to be uplifted a minimum of 48.5% | H3: Rev License
A4: Contact MAS project office for pricing guidance /non standard pricing; Consult the 7.14 Play for Uplifts on RTM shifts and guidance
A7: Is this an FCT client (y/n) | C7: (If NO, leave cell "A11" blank )
A9: MAS Perpetual Pricing (USD) / Update to Local Currency if outside US and note currency being used (confirm from SQO)
A10: LPP on FCT 2022 (Provided by the FCT S&S rep) | B10: LPP on PA uplifted 0% from FCT LPP (Provided by S&S rep) | C10: MAS Uplift of 48.5% | D10: MAS Points needed (qty for the Tradeup part number D29HYLL) | E10: TradeUp Price /Point (Local Currency) | F10: TradeUp Yearly List Price | G10: Discount | H10: Net Price/Year | I10: S&S | J10: Sales
C11: =B11*1.485 -> 0 | E11: 664 | F11: =D11*E11 -> 0 | G11: =1-(H11/F11) -> #DIV/0! | H11: =C11 -> 0 | I11: =(+H11*0.7407) -> 0 | J11: =(+H11*0.2593) -> 0
F13: =+F11 -> 0 | G13: Year 2 | H13: =(+H11*0.7407)*1.1 -> 0 | I13: S&S Organization has delegation on non-committed outyear Uplifts
F14: =+F13 -> 0 | G14: Year 3 | H14: =+H13*1.1 -> 0 | I14: S&S Organization has delegation on non-committed outyear Uplifts
F15: =+F14 -> 0 | G15: Year 4 | H15: =+H14*1.1 -> 0 | I15: S&S Organization has delegation on non-committed outyear Uplifts
F16: =+F15 -> 0 | G16: Year 5 | H16: =+H15*1.1 -> 0 | I16: MAS Trans Bookable
F17: =F11+F13+F14 -> 0 | G17: TOTAL 3yr | H17: =H11+H13+H14 -> 0 | I17: =+H11*0.2593 -> 0
F18: =F17+F15+F16 -> 0 | G18: TOTAL 5yr | H18: =H17+H15+H16 -> 0 | I18: =+H11*0.2593 -> 0
A19: MAS Managed Services | I19: =H19*0.11 -> 0
A20: Concurrent Users | B20: Services | C20: VPC | D20: GB | E20: Unit List Price | G20: Discount | H20: Net Price /Year
A31: RTM Shift Scenario outside of the Play approved scenarios or when Geo rates are not available in the Play:
A33: MAS Perpetual Pricing (USD) / Update to local currency if ouside US and note currency being used
A34: LPP on FCT 2022 (Provided by the FCT S&S rep) | B34: LPP on PA uplifted 0% from FCT LPP (Provided by S&S rep) | C34: MAS Uplift of 48.5% | D34: MAS Points needed (qty for the Tradeup part number D29HYLL) | E34: TradeUp Price /Point (Local Currency) | F34: TradeUp Yearly List Price | G34: Discount | H34: Net Price/Year | I34: S&S | J34: Sales | K34: Add'l Incentive Uplifts if required (modify the % based on Lamar Murphy input) | L34: Min Price required w RTM Shift | M34: Discount
C35: =B35*1.485 -> 0 | E35: 664 | F35: =D35*E35 -> 0 | G35: =1-(H35/F35) -> #DIV/0! | H35: =C35 -> 0 | I35: =(+H35*0.7407) -> 0 | J35: =(+H35*0.2593) -> 0 | K35: 0.12 | L35: =H35*(1+K35) -> 0 | M35: =1-L35/F35 -> #DIV/0!
F37: =+F35 -> 0 | G37: Year 2 | H37: =(+H35*0.7407)*1.1 -> 0 | I37: S&S Organization has delegation on non-committed outyear Uplifts
F38: =+F37 -> 0 | G38: Year 3 | H38: =+H37*1.1 -> 0 | I38: S&S Organization has delegation on non-committed outyear Uplifts
F39: =+F38 -> 0 | G39: Year 4 | H39: =+H38*1.1 -> 0 | I39: S&S Organization has delegation on non-committed outyear Uplifts
F40: =+F39 -> 0 | G40: Year 5 | H40: =+H39*1.1 -> 0 | I40: MAS Trans Bookable
F41: =F35+F37+F38 -> 0 | G41: TOTAL 3yr | H41: =H35+H37+H38 -> 0 | I41: =+H35*0.2593 -> 0
F42: =F41+F39+F40 -> 0 | G42: TOTAL 5yr | H42: =H41+H39+H40 -> 0 | I42: =+H35*0.2593 -> 0

Sheet List of Eligible Parts
A2: UT_LEVEL_CODE_30_DSCR | B2: IBM_SW_FAM_CODE | C2: IBM_PROD_ID | D2: IBM_PROD_ID_DSCR | E2: WWIDE_PROD_CODE_DSCR | F2: Eligible Part # | G2: Eligible Part Description | H2: Eligible Part Parent Lic + S&S Part # | I2: CU_DSCR | J2: Part Type
A3: Enterprise Asset Management | B3: MXA ANYWHERE | C3: 5725M39 | D3: IBM Maximo Anywhere | E3: Maximo Anywhere | F3: E0K39LL | G3: IBM MAXIMO ANYWHERE ADD-ON AUTHORIZED USER ANNUAL SW SUBSCRIPTION & SUPPORT RENEWAL | H3: D17CCLL | I3: Authorized User | J3: Renewal
A4: Enterprise Asset Management | B4: MXA ANYWHERE | C4: 5725M39 | D4: IBM Maximo Anywhere | E4: Maximo Anywhere | F4: D17CCLL | G4: IBM MAXIMO ANYWHERE ADD-ON AUTHORIZED USER LICENSE + SW SUBSCRIPTION & SUPPORT 12 MONTHS | H4: D17CCLL | I4: Authorized User | J4: License + S&S
A5: Enterprise Asset Management | B5: MXA ANYWHERE | C5: 5725M39 | D5: IBM Maximo Anywhere | E5: Maximo Anywhere | F5: D17CDLL | G5: IBM MAXIMO ANYWHERE ADD-ON AUTHORIZED USER SW SUBSCRIPTION & SUPPORT REINSTATEMENT 12 MONTHS | H5: D17CCLL | I5: Authorized User | J5: Reinstatement
A6: Enterprise Asset Management | B6: MXA ANYWHERE | C6: 5725M39 | D6: IBM Maximo Anywhere | E6: Maximo Anywhere | F6: E0N3QLL | G6: IBM MAXIMO ANYWHERE ADD-ON CONCURRENT USER ANNUAL SW SUBSCRIPTION & SUPPORT RENEWAL 12 MONTHS | H6: D1QBGLL | I6: Concurrent User | J6: Renewal
A7: Enterprise Asset Management | B7: MXA ANYWHERE | C7: 5725M39 | D7: IBM Maximo Anywhere | E7: Maximo Anywhere | F7: D1QBGLL | G7: IBM MAXIMO ANYWHERE ADD-ON CONCURRENT USER LICENSE + SW SUBSCRIPTION & SUPPORT 12 MONTHS | H7: D1QBGLL | I7: Concurrent User | J7: License + S&S
A8: Enterprise Asset Management | B8: MXA ANYWHERE | C8: 5725M39 | D8: IBM Maximo Anywhere | E8: Maximo Anywhere | F8: D1QBHLL | G8: IBM MAXIMO ANYWHERE ADD-ON CONCURRENT USER SW SUBSCRIPTION & SUPPORT REINSTATEMENT 12 MONTHS | H8: D1QBGLL | I8: Concurrent User | J8: Reinstatement
A9: Enterprise Asset Management | B9: MXA ANYWHERE | C9: 5725M39 | D9: IBM Maximo Anywhere | E9: Maximo Anywhere | F9: D1QBMLL | G9: IBM MAXIMO ANYWHERE ADD-ON CONCURRENT USER LINUX ON Z SYSTEM TRADE UP FROM 3 MAXIMO ANYWHERE ADD-ON AUTHORIZED USER ON Z SYSTEM + SW SUBSCRIPTION & SUPPORT 12 MONTHS | H9: D1QBKLL | I9: Concurrent User | J9: Trade-Up
A10: Enterprise Asset Management | B10: MXA ANYWHERE | C10: 5725M39 | D10: IBM Maximo Anywhere | E10: Maximo Anywhere | F10: E0N3RLL | G10: IBM MAXIMO ANYWHERE ADD-ON CONCURRENT USER LINUX Z SYSTEM ANNUAL SW SUBSCRIPTION & SUPPORT RENEWAL | H10: D1QBKLL | I10: Concurrent User | J10: Renewal
A11: Enterprise Asset Management | B11: MXA ANYWHERE | C11: 5725M39 | D11: IBM Maximo Anywhere | E11: Maximo Anywhere | F11: D1QBKLL | G11: IBM MAXIMO ANYWHERE ADD-ON CONCURRENT USER LINUX Z SYSTEM SW SUBSCRIPTION & SUPPORT 12 MONTHS | H11: D1QBKLL | I11: Concurrent User | J11: License + S&S
A12: Enterprise Asset Management | B12: MXA ANYWHERE | C12: 5725M39 | D12: IBM Maximo Anywhere | E12: Maximo Anywhere | F12: D1QBLLL | G12: IBM MAXIMO ANYWHERE ADD-ON CONCURRENT USER LINUX Z SYSTEM SW SUBSCRIPTION & SUPPORT REINSTATEMENT 12 MONTHS | H12: D1QBKLL | I12: Concurrent User | J12: Reinstatement
A13: Enterprise Asset Management | B13: MXA ANYWHERE | C13: 5725M39 | D13: IBM Maximo Anywhere | E13: Maximo Anywhere | F13: D1QBILL | G13: IBM MAXIMO ANYWHERE ADD-ON CONCURRENT USER TRADE UP FROM 3 MAXIMO ANYWHERE ADD-ON AUTHORIZED USER + SW SUBSCRIPTION & SUPPORT 12 MONTHS | H13: D1QBGLL | I13: Concurrent User | J13: Trade-Up
... A505: Maximo | B505: MVI | C505: 5737H10 | D505: IBM Maximo Visual Inspections | E505: Maximo Visual Inspections | F505: D1Y6BLL | G505: IBM Maximo Visual Inspections | H505: D1Y6BLL | I505: per vServer | J505: License + S&S
A506: APM | B506: EMA | D506: IBM Maximo Equipment Maintenance Assistant | E506: Maximo Equipment Maintenance Assistant | F506: E0QC7LL | G506: IBM MAXIMO EQUIPMENT MAINTENANCE ASSISTANT BASE PER 48 VIRTUAL PROCESSOR CORES ANNUAL SW SUBSCRIPTION & SUPPORT RENEWAL 12 MONTHS | H506: E0QC7LL | I506: VPC | J506: Renewal
A507: APM | B507: EMA | D507: IBM Maximo Equipment Maintenance Assistant | E507: Maximo Equipment Maintenance Assistant | F507: D24Z1LL | G507: IBM MAXIMO EQUIPMENT MAINTENANCE ASSISTANT BASE PER 48 VIRTUAL PROCESSOR CORES LICENSE + SW SUBSCRIPTION & SUPPORT 12 MONTHS | H507: D24Z1LL | I507: VPC | J507: License + S&S
A508: APM | B508: EMA | D508: IBM Maximo Equipment Maintenance Assistant | E508: Maximo Equipment Maintenance Assistant | F508: E0QC8LL | G508: IBM MAXIMO EQUIPMENT MAINTENANCE ASSISTANT PER RESOURCE VALUE UNIT ANNUAL SW SUBSCRIPTION & SUPPORT RENEWAL 12 MONTHS | H508: E0QC8LL | I508: RVU | J508: Renewal
A509: APM | B509: EMA | D509: IBM Maximo Equipment Maintenance Assistant | E509: Maximo Equipment Maintenance Assistant | F509: D24Z4LL | G509: IBM MAXIMO EQUIPMENT MAINTENANCE ASSISTANT PER RESOURCE VALUE UNIT LICENSE + SW SUBSCRIPTION & SUPPORT 12 MONTHS | H509: D24Z4LL | I509: RVU | J509: License + S&S
A510: Asset Performance Management | B510: ENERGY SIGHT | C510: 5725W39 | D510: IBM Maximo Ass Perf Mgnt for Engy & Uti On-prem | E510: Max APM for Energy & Utilities | F510: E0LT5LL | G510: IBM MAXIMO APM FOR E&U ON-PREMISE - ASSETS PER RESOURCE VALUE UNIT ANNUAL SW SUBSCRIPTION & SUPPORT RENEWAL | H510: D1I2WLL | I510: RVU | J510: Renewal
A511: Asset Performance Management | B511: ENERGY SIGHT | C511: 5725W39 | D511: IBM Maximo Ass Perf Mgnt for Engy & Uti On-prem | E511: Max APM for Energy & Utilities | F511: D1I2WLL | G511: IBM MAXIMO APM FOR E&U ON-PREMISE - ASSETS PER RESOURCE VALUE UNIT LICENSE + SW SUBSCRIPTION & SUPPORT 12 MONTHS | H511: D1I2WLL | I511: RVU | J511: License + S&S
A512: Asset Performance Management | B512: ENERGY SIGHT | C512: 5725W39 | D512: IBM Maximo Ass Perf Mgnt for Engy & Uti On-prem | E512: Max APM for Energy & Utilities | F512: D1I2XLL | G512: IBM MAXIMO APM FOR E&U ON-PREMISE - ASSETS PER RESOURCE VALUE UNIT SW SUBSCRIPTION & SUPPORT REINSTATEMENT 12 MONTHS | H512: D1I2WLL | I512: ERVU | J512: Reinstatement
A513: Asset Performance Management | B513: ENERGY SIGHT | C513: 5725W39 | D513: IBM Maximo Ass Perf Mgnt for Engy & Uti On-prem | E513: Max APM for Energy & Utilities | F513: E0LT3LL | G513: IBM MAXIMO APM FOR E&U ON-PREMISE - LIMITED USER PER USER VALUE UNIT ANNUAL SW SUBSCRIPTION & SUPPORT RENEWAL | H513: D1I2TLL | I513: User Value Unit | J513: Renewal
A514: Asset Performance Management | B514: ENERGY SIGHT | C514: 5725W39 | D514: IBM Maximo Ass Perf Mgnt for Engy & Uti On-prem | E514: Max APM for Energy & Utilities | F514: D1I2TLL | G514: IBM MAXIMO APM FOR E&U ON-PREMISE - LIMITED USER PER USER VALUE UNIT LICENSE + SW SUBSCRIPTION & SUPPORT 12 MONTHS | H514: D1I2TLL | I514: User Value Unit | J514: License + S&S
A515: Asset Performance Management | B515: ENERGY SIGHT | C515: 5725W39 | D515: IBM Maximo Ass Perf Mgnt for Engy & Uti On-prem | E515: Max APM for Energy & Utilities | F515: D1I2ULL | G515: IBM MAXIMO APM FOR E&U ON-PREMISE - LIMITED USER PER USER VALUE UNIT SW SUBSCRIPTION & SUPPORT REINSTATEMENT 12 MONTHS | H515: D1I2TLL | I515: User Value Unit | J515: Reinstatement
A516: Asset Performance Management | B516: ENERGY SIGHT | C516: 5725W39 | D516: IBM Maximo Ass Perf Mgnt for Engy & Uti On-prem | E516: Max APM for Energy & Utilities | F516: E0LT2LL | G516: IBM MAXIMO APM FOR E&U ON-PREMISE - STANDARD USER PER AUTHORIZED USER ANNUAL SW SUBSCRIPTION & SUPPORT RENEWAL | H516: D1I2QLL | I516: Authorized User | J516: Renewal
A517: Asset Performance Management | B517: ENERGY SIGHT | C517: 5725W39 | D517: IBM Maximo Ass Perf Mgnt for Engy & Uti On-prem | E517: Max APM for Energy & Utilities | F517: D1I2QLL | G517: IBM MAXIMO APM FOR E&U ON-PREMISE - STANDARD USER PER AUTHORIZED USER LICENSE + SW SUBSCRIPTION & SUPPORT 12 MONTHS | H517: D1I2QLL | I517: Authorized User | J517: License + S&S
A518: Asset Performance Management | B518: ENERGY SIGHT | C518: 5725W39 | D518: IBM Maximo Ass Perf Mgnt for Engy & Uti On-prem | E518: Max APM for Energy & Utilities | F518: D1I2RLL | G518: IBM MAXIMO APM FOR E&U ON-PREMISE - STANDARD USER PER AUTHORIZED USER SW SUBSCRIPTION & SUPPORT REINSTATEMENT 12 MONTHS | H518: D1I2QLL | I518: Authorized User | J518: Reinstatement
A519: Asset Performance Management | B519: ENERGY SIGHT | C519: 5725W39 | D519: IBM Maximo Ass Perf Mgnt for Engy & Uti On-prem | E519: Max APM for Energy & Utilities | F519: E0P37LL | G519: IBM MAXIMO APM FOR E&U ON-PREMISE - STANDARD USER PER CONCURRENT USER ANNUAL SW SUBSCRIPTION & SUPPORT RENEWAL | H519: D1W7FLL | I519: Concurrent User | J519: Renewal
A520: Asset Performance Management | B520: ENERGY SIGHT | C520: 5725W39 | D520: IBM Maximo Ass Perf Mgnt for Engy & Uti On-prem | E520: Max APM for Energy & Utilities | F520: D1W7FLL | G520: IBM MAXIMO APM FOR E&U ON-PREMISE - STANDARD USER PER CONCURRENT USER LICENSE + SW SUBSCRIPTION & SUPPORT 12 MONTHS | H520: D1W7FLL | I520: Concurrent User | J520: License + S&S
A521: Asset Performance Management | B521: ENERGY SIGHT | C521: 5725W39 | D521: IBM Maximo Ass Perf Mgnt for Engy & Uti On-prem | E521: Max APM for Energy & Utilities | F521: D1W7GLL | G521: IBM MAXIMO APM FOR E&U ON-PREMISE - STANDARD USER PER CONCURRENT USER SW SUBSCRIPTION & SUPPORT REINSTATEMENT 12 MONTHS | H521: D1W7FLL | I521: Concurrent User | J521: Reinstatement
A522: Enterprise Asset Management | B522: MAXIMO | C522: 5724U18 | D522: IBM Maximo Asset Management | E522: IBM Maximo Asset Management | F522: E05B6LL | G522: IBM MAXIMO ASSET MANAGEMENT INTERNAL SERVICE PROVIDERS INSTALL + SW SUBSCRIPTION & SUPPORT 12 MONTHS | H522: E05B6LL | I522: User | J522: Renewal | P522: 1070 | Q522: renewal | R522: INTERNAL SERVICE PROVIDERS | S522: ADD-ON | T522: Install | U522: =IF(ISNUMBER(SEARCH("ADD-ON",$I522)),"ADD-ON","NOT AN ADD-ON") -> NOT AN ADD-ON
A523: Enterprise Asset Management | B523: MAXIMO | C523: 5724U18 | D523: IBM Maximo Asset Management | E523: IBM Maximo Asset Management | F523: D28NMLL | G523: IBM MAXIMO SCHEDULER OPTIMIZATION PER INSTALL LICENSE + SW SUBSCRIPTION & SUPPORT 12 MONTHS | H523: E05B6LL | I523: Install | J523: License + S&S | P523: 1070 | Q523: renewal | R523: INTERNAL SERVICE PROVIDERS | S523: ADD-ON | T523: Install | U523: =IF(ISNUMBER(SEARCH("ADD-ON",$I523)),"ADD-ON","NOT AN ADD-ON") -> NOT AN ADD-ON
A524: Enterprise Asset Management | B524: MAXIMO | C524: 5724U18 | D524: IBM Maximo Asset Management | E524: IBM Maximo Asset Management | F524: E0R3ELL | G524: IBM MAXIMO SCHEDULER OPTIMIZATION PER INSTALL ANNUAL SW SUBSCRIPTION & SUPPORT RENEWAL | H524: E05B6LL | I524: Install | J524: Renewal | P524: 1070 | Q524: renewal | R524: INTERNAL SERVICE PROVIDERS | S524: ADD-ON | T524: Install | U524: =IF(ISNUMBER(SEARCH("ADD-ON",$I524)),"ADD-ON","NOT AN ADD-ON") -> NOT AN ADD-ON
A525: Enterprise Asset Management | B525: MAXIMO | C525: 5725U87 | D525: IBM Maximo Asset Management | E525: IBM Maximo Asset Management | F525: D20V8LL | G525: IBM MAXIMO FOR AVIATION MAINTENANCE OPTIMIZATION INSTALL LICENSE SW SUBSCRIPTION & SUPPORT 12 MONTHS | H525: E05B6LL | I525: Install | J525: License + S&S | P525: 1070 | Q525: renewal | R525: INTERNAL SERVICE PROVIDERS | S525: ADD-ON | T525: Install | U525: =IF(ISNUMBER(SEARCH("ADD-ON",$I525)),"ADD-ON","NOT AN ADD-ON") -> NOT AN ADD-ON
A526: Enterprise Asset Management | B526: MAXIMO | C526: 5725U87 | D526: IBM Maximo Asset Management | E526: IBM Maximo Asset Management | F526: E0PNBLL | G526: IBM MAXIMO FOR AVIATION MAINTENANCE OPTIMIZATION INSTALL LICENCE ANNUAL SW SUBSCRIPTION & SUPPORT RENEWAL | H526: E05B6LL | I526: Install | J526: Renewal | P526: 1070 | Q526: renewal | R526: INTERNAL SERVICE PROVIDERS | S526: ADD-ON | T526: Install | U526: =IF(ISNUMBER(SEARCH("ADD-ON",$I526)),"ADD-ON","NOT AN ADD-ON") -> NOT AN ADD-ON
A527: Asset Performance Management | B527: ENERGY SIGHT | C527: 5725W39 | D527: IBM Maximo Ass Perf Mgnt for Engy & Uti On-prem | E527: Max APM for Energy & Utilities | F527: D1W7HLL | G527: IBM MAXIMO APM FOR E&U ON-PREMISE - DECISION OPTIMIZATION USER PER CONCURRENT USER LICENSE + SW SUBSCRIPTION & SUPPORT 12 MONTHS | H527: D1W7HLL | I527: User | J527: License + S&S
A528: Asset Performance Management | B528: ENERGY SIGHT | C528: 5725W39 | D528: IBM Maximo Ass Perf Mgnt for Engy & Uti On-prem | E528: Max APM for Energy & Utilities | F528: E0P38LL | G528: IBM MAXIMO APM FOR E&U ON-PREMISE - DECISION OPTIMIZATION USER PER CONCURRENT USER ANNUAL SW SUBSCRIPTION & SUPPORT RENEWAL | H528: E0P38LL | I528: User | J528: Reinstatement

Sheet Version
A1: Date | B1: Version | C1: Changes
A2: 11/24/2020 | B2: 5.4 | C2: Updated New Deal Calculator tab - N/A error on MVI after first row
A3: 11/25/2020 | B3: 5.4a | C3: Rounded to the 5th on Upgrade/Tradeup Total cell
A4: 12/14/2020 | B4: 5.4b | C4: Added new Line Item Description column to New Deal Calc tab & sorted Upgrade/Tradeup lookup list
A5: 01/07/2021 | B5: 6 | C5: Added Assist, APM4EU, MVI Edge to New Deal tab, Assist/APM4EU parts to Upgrade and Tradeup tabs
A6: 03/12/2021 | B6: 6.1 | C6: Updated Perpetual Trade-up Pricing tab to add S&S and Sales perentages along with YoY at 10% per S&S request/ Updated Note section in New Deal tab
A7: 04/06/2021 | B7: 6.2 | C7: Added Civil Infrastructure Install AppPoints on New Deal tab
A8: 06/14/2021 | B8: 6.3 | C8: Updated default List Price on Pricing tabs
A9: 06/22/2021 | B9: 6.3a | C9: Added additional rows to the Upgrade/Trade up tabs
A10: 08/16/2021 | B10: 6.4 | C10: Addition of Authorized Users to New Deal and Updated Sales S&S on Trade-up Pricing tab
A11: 10/05/2021 | B11: 6.5 | C11: Addition of Eligible Parts tab and details added to Pricing tabs
A12: 11/04/2021 | B12: 6.5a | C12: Added part numbers to the upgrade/tradeup pricing tabs
A13: 05/22/2022 | B13: 6.5b | C13: corrected aviation CU mapping part to 15 app points vs 5.
A14: 06/02/2022 | B14: 6.5c | C14: addition of SP internal Install part
A15: 07/26/2022 | B15: 7 | C15: addition of Maximo Optimizer along with update of Edge as 1 AppPoint
A16: 10/26/2022 | B16: 7a | C16: updated add-on AppPoints to authorized plus addition of upfront and annual pricing to subscription pricing tab
A17: 10/28/2022 | B17: 7b | C17: updated HSE concurrent

Sheet New Parts
E2: Required AppPoints
C3: Install | D3: ADAPTER FOR ORACLE | E3: 80
C4: Install | D4: ADAPTER FOR SAP | E4: 80
C5: Limited Concurrent User | D5: ANYWHERE | E5: 5
C6: Premium Concurrent User | D6: ASSET CONFIGURATION MANAGER | E6: 15
C7: Limited Concurrent User | D7: ASSET CONFIGURATION MANAGER LIMITED | E7: 5
C8: Base Concurrent User | D8: ASSET MANAGEMENT (CORE) | E8: 10
C9: Limited Concurrent User | D9: ASSET MANAGEMENT (CORE) LIMITED | E9: 5
C10: Premium Concurrent User | D10: AVIATION | E10: 15
C11: Limited Concurrent User | D11: AVIATION LIMITED | E11: 5
C12: Premium Concurrent User | D12: CIVIL INFRASTRUCTRE | E12: 15
C13: Limited Concurrent User | D13: CIVIL INFRASTRUCTURE LIMITED | E13: 5
C14: Premium Concurrent User | D14: HEALTH SAFETY & ENVIORNMENT | E14: 15
... C26: Limited Concurrent User | D26: UTILITIES LIMITED | E26: 5
D27: CALIBRATION FULL | E27: 10
D28: CALIBRATION LIMITED | E28: 5
D29: LINEAR FULL | E29: 10
D30: LINEAR LIMITED | E30: 5
D31: SCHEDULER FULL | E31: 10
D33: SPATIAL FULL | E33: 10
D34: SPATIAL LIMITED | E34: 5
D37: Admin Premium User | E37: 15
D38: Admin Base User | E38: 10
D39: Premium Concurrent User | E39: 15
D40: Base Concurrent User | E40: 10
D41: Limited Concurrent User | E41: 5
... D54: Install - Optimizer Limited | E54: 60

Sheet Upgrade Parts Future_K_v5.4
A2: UT_LEVEL_CODE_30_DSCR | B2: IBM_SW_PILLAR_CODE | C2: IBM_SW_FAM_CODE | D2: IBM_PROD_ID | E2: IBM_PROD_ID_DSCR | F2: WWIDE_PROD_CODE_DSCR | G2: Eligible Part List Price | H2: Eligible Part # | I2: Eligible Part Description | J2: Eligible Part Parent Lic + S&S Part # | K2: CU_DSCR | L2: AppPoint for upgrade | M2: Upgrade Price Metric Conversion | N2: MAS AppPoint (Ltd, Base, Prm) | O2: Price Metric Conversion | P2: Parent Lic + S&S Part # US List Price | Q2: Part Type | R2: Offering name | S2: Core/IS/Add-ons/Anywhere | T2: AUTHORIZED | U2: Add-on Parts
A3: Enterprise Asset Management | B3: MAXIMO | C3: MXA CONFIG | D3: 5724U28 | E3: IBM Maximo Asset Configuration Manager | F3: Maximo Asset Configuration Manager | G3: 8980 | H3: D03WULL | I3: IBM MAXIMO ASSET CONFIGURATION MANAGER ASSET LICENSE + SW SUBSCRIPTION & SUPPORT 12 MONTHS | J3: D03WULL | K3: Asset | L3: Manual Input required | M3: =ROUND(IF(K3="Authorized User",L3/3,L3),2) -> #VALUE! | N3: 15 | O3: 5 | P3: 8980 | Q3: License + S&S | R3: ASSET CONFIGURATION MANAGER | S3: ACM | T3: ASSET | U3: =IF(ISNUMBER(SEARCH("ADD-ON",$I3)),"ADD-ON","NOT AN ADD-ON") -> NOT AN ADD-ON | V3: =CONCATENATE(R3,S3,T3,U3) -> ASSET CONFIGURATION MANAGERACMASSETNOT AN ADD-ON
A4: Enterprise Asset Management | B4: MAXIMO | C4: MXA CONFIG | D4: 5724U28 | E4: IBM Maximo Asset Configuration Manager | F4: Maximo Asset Configuration Manager | G4: 5390 | H4: D03WVLL | I4: IBM MAXIMO ASSET CONFIGURATION MANAGER ASSET SW SUBSCRIPTION & SUPPORT REINSTATEMENT 12 MONTHS | J4: D03WULL | K4: Asset | L4: Manual Input required | M4: =ROUND(IF(K4="Authorized User",L4/3,L4),2) -> #VALUE! | N4: 15 | O4: 5 | P4: 8980 | Q4: Reinstatement | R4: ASSET CONFIGURATION MANAGER | S4: ACM | T4: ASSET | U4: =IF(ISNUMBER(SEARCH("ADD-ON",$I4)),"ADD-ON","NOT AN ADD-ON") -> NOT AN ADD-ON | V4: =CONCATENATE(R4,S4,T4,U4) -> ASSET CONFIGURATION MANAGERACMASSETNOT AN ADD-ON
A5: Enterprise Asset Management | B5: MAXIMO | C5: MXA CONFIG | D5: 5724U28 | E5: IBM Maximo Asset Configuration Manager | F5: Maximo Asset Configuration Manager | G5: 5740 | H5: D03WYLL | I5: IBM MAXIMO ASSET CONFIGURATION MANAGER AUTHORIZED USER LICENSE + SW SUBSCRIPTION & SUPPORT 12 MONTHS | J5: D03WYLL | K5: Authorized User | L5: 15 | M5: =ROUND(IF(K5="Authorized User",L5/3,L5),2) -> 5 | N5: 15 | O5: 5 | P5: 5740 | Q5: License + S&S | R5: ASSET CONFIGURATION MANAGER | S5: ACM | T5: AUTHORIZED | U5: =IF(ISNUMBER(SEARCH("ADD-ON",$I5)),"ADD-ON","NOT AN ADD-ON") -> NOT AN ADD-ON | V5: =CONCATENATE(R5,S5,T5,U5) -> ASSET CONFIGURATION MANAGERACMAUTHORIZEDNOT AN ADD-ON
A6: Enterprise Asset Management | B6: MAXIMO | C6: MXA CONFIG | D6: 5724U28 | E6: IBM Maximo Asset Configuration Manager | F6: Maximo Asset Configuration Manager | G6: 3440 | H6: D03WZLL | I6: IBM MAXIMO ASSET CONFIGURATION MANAGER AUTHORIZED USER SW SUBSCRIPTION & SUPPORT REINSTATEMENT 12 MONTHS | J6: D03WYLL | K6: Authorized User | L6: 15 | M6: =ROUND(IF(K6="Authorized User",L6/3,L6),2) -> 5 | N6: 15 | O6: 5 | P6: 5740 | Q6: Reinstatement | R6: ASSET CONFIGURATION MANAGER | S6: ACM | T6: AUTHORIZED | U6: =IF(ISNUMBER(SEARCH("ADD-ON",$I6)),"ADD-ON","NOT AN ADD-ON") -> NOT AN ADD-ON | V6: =CONCATENATE(R6,S6,T6,U6) -> ASSET CONFIGURATION MANAGERACMAUTHORIZEDNOT AN ADD-ON
A7: Enterprise Asset Management | B7: MAXIMO | C7: MXA CALIBRAT | D7: 5724U33 | E7: IBM Maximo Calibration | F7: Maximo Calibration | G7: 584 | H7: D03X4LL | I7: IBM MAXIMO CALIBRATION AUTHORIZED USER LICENSE + SW SUBSCRIPTION & SUPPORT 12 MONTHS | J7: D03X4LL | K7: Authorized User | L7: 0 | M7: =ROUND(IF(K7="Authorized User",L7/3,L7),2) -> 0 | N7: 5 | O7: 1.6666667 | P7: 584 | Q7: License + S&S | R7: CALIBRATION | S7: ADD-ON | T7: AUTHORIZED | U7: =IF(ISNUMBER(SEARCH("ADD-ON",$I7)),"ADD-ON","NOT AN ADD-ON") -> NOT AN ADD-ON | V7: =CONCATENATE(R7,S7,T7,U7) -> CALIBRATIONADD-ONAUTHORIZEDNOT AN ADD-ON
A8: Enterprise Asset Management | B8: MAXIMO | C8: MXA CALIBRAT | D8: 5724U33 | E8: IBM Maximo Calibration | F8: Maximo Calibration | G8: 350 | H8: D03X5LL | I8: IBM MAXIMO CALIBRATION AUTHORIZED USER SW SUBSCRIPTION & SUPPORT REINSTATEMENT 12 MONTHS | J8: D03X4LL | K8: Authorized User | L8: 0 | M8: =ROUND(IF(K8="Authorized User",L8/3,L8),2) -> 0 | N8: 5 | O8: 1.6666667 | P8: 584 | Q8: Reinstatement | R8: CALIBRATION | S8: ADD-ON | T8: AUTHORIZED | U8: =IF(ISNUMBER(SEARCH("ADD-ON",$I8)),"ADD-ON","NOT AN ADD-ON") -> NOT AN ADD-ON | V8: =CONCATENATE(R8,S8,T8,U8) -> CALIBRATIONADD-ONAUTHORIZEDNOT AN ADD-ON
A9: Enterprise Asset Management | B9: MAXIMO | C9: MXA LINEAR | D9: 5724U18 | E9: IBM Maximo Asset Management | F9: Maximo Asset Management | G9: 712 | H9: D040SLL | I9: IBM MAXIMO LINEAR ASSET MANAGER AUTHORIZED USER LICENSE + SW SUBSCRIPTION & SUPPORT 12 MONTHS | J9: D040SLL | K9: Authorized User | L9: 0 | M9: =ROUND(IF(K9="Authorized User",L9/3,L9),2) -> 0 | N9: 5 | O9: 1.6666667 | P9: 712 | Q9: License + S&S | R9: LINEAR | S9: ADD-ON | T9: AUTHORIZED | U9: =IF(ISNUMBER(SEARCH("ADD-ON",$I9)),"ADD-ON","NOT AN ADD-ON") -> NOT AN ADD-ON | V9: =CONCATENATE(R9,S9,T9,U9) -> LINEARADD-ONAUTHORIZEDNOT AN ADD-ON
A10: Enterprise Asset Management | B10: MAXIMO | C10: MXA LINEAR | D10: 5724U18 | E10: IBM Maximo Asset Management | F10: Maximo Asset Management | G10: 427 | H10: D040TLL | I10: IBM MAXIMO LINEAR ASSET MANAGER AUTHORIZED USER SW SUBSCRIPTION & SUPPORT REINSTATEMENT 12 MONTHS | J10: D040SLL | K10: Authorized User | L10: 0 | M10: =ROUND(IF(K10="Authorized User",L10/3,L10),2) -> 0 | N10: 5 | O10: 1.6666667 | P10: 712 | Q10: Reinstatement | R10: LINEAR | S10: ADD-ON | T10: AUTHORIZED | U10: =IF(ISNUMBER(SEARCH("ADD-ON",$I10)),"ADD-ON","NOT AN ADD-ON") -> NOT AN ADD-ON | V10: =CONCATENATE(R10,S10,T10,U10) -> LINEARADD-ONAUTHORIZEDNOT AN ADD-ON
A11: Enterprise Asset Management | B11: MAXIMO | C11: MX ENT ADP | D11: 5724T00 | E11: IBM Maximo Enterprise Adapter | F11: Maximo Enterprise Adapter | G11: 161000 | H11: D04QDLL | I11: IBM MAXIMO ENTERPRISE ADAPTER FOR SAP APPLICATIONS SERVER LICENSE + SW SUBSCRIPTION & SUPPORT 12 MONTHS | J11: D04QDLL | K11: Server | L11: 80 | M11: =ROUND(IF(K11="Authorized User",L11/3,L11),2) -> 80 | N11: 80 | O11: 1 | P11: 161000 | Q11: License + S&S | R11: ADAPTER FOR SAP | S11: ADAPTER | T11: ADAPTER | U11: =IF(ISNUMBER(SEARCH("ADD-ON",$I11)),"ADD-ON","NOT AN ADD-ON") -> NOT AN ADD-ON | V11: =CONCATENATE(R11,S11,T11,U11) -> ADAPTER FOR SAPADAPTERADAPTERNOT AN ADD-ON
A12: Enterprise Asset Management | B12: MAXIMO | C12: MX ENT ADP | D12: 5724T00 | E12: IBM Maximo Enterprise Adapter | F12: Maximo Enterprise Adapter | G12: 96300 | H12: D04QELL | I12: IBM MAXIMO ENTERPRISE ADAPTER FOR SAP APPLICATIONS SERVER SW SUBSCRIPTION & SUPPORT REINSTATEMENT 12 MONTHS | J12: D04QDLL | K12: Server | L12: 80 | M12: =ROUND(IF(K12="Authorized User",L12/3,L12),2) -> 80 | N12: 80 | O12: 1 | P12: 161000 | Q12: Reinstatement | R12: ADAPTER FOR SAP | S12: ADAPTER | T12: ADAPTER | U12: =IF(ISNUMBER(SEARCH("ADD-ON",$I12)),"ADD-ON","NOT AN ADD-ON") -> NOT AN ADD-ON | V12: =CONCATENATE(R12,S12,T12,U12) -> ADAPTER FOR SAPADAPTERADAPTERNOT AN ADD-ON
A13: Enterprise Asset Management | B13: MAXIMO | C13: MXS EAM | D13: 5724U18 | E13: IBM Maximo Asset Management | F13: Maximo Asset Management | G13: 1780 | H13: D04XSLL | I13: IBM MAXIMO ASSET MANAGEMENT MANAGED SERVICE PROVIDERS LIMITED USE AUTHORIZED USER LICENSE + SW SUBSCRIPTION & SUPPORT 12 MONTHS | J13: D04XSLL | K13: Authorized User | L13: 0 | M13: =ROUND(IF(K13="Authorized User",L13/3,L13),2) -> 0 | N13: 5 | O13: 1.6666667 | P13: 1780 | Q13: License + S&S | R13: MANAGED SERVICE PROVIDERS | S13: MSP | T13: LIMITED | U13: =IF(ISNUMBER(SEARCH("ADD-ON",$I13)),"ADD-ON","NOT AN ADD-ON") -> NOT AN ADD-ON | V13: =CONCATENATE(R13,S13,T13,U13) -> MANAGED SERVICE PROVIDERSMSPLIMITEDNOT AN ADD-ON
A14: Enterprise Asset Management | B14: MAXIMO | C14: MXS EAM | D14: 5724U18 | E14: IBM Maximo Asset Management | F14: Maximo Asset Management | G14: 1070 | H14: D04XTLL | I14: IBM MAXIMO ASSET MANAGEMENT MANAGED SERVICE PROVIDERS LIMITED USE AUTHORIZED USER SW SUBSCRIPTION & SUPPORT REINSTATEMENT 12 MONTHS | J14: D04XSLL | K14: Authorized User | L14: 0 | M14: =ROUND(IF(K14="Authorized User",L14/3,L14),2) -> 0 | N14: 5 | O14: 1.6666667 | P14: 1780 | Q14: Reinstatement | R14: MANAGED SERVICE PROVIDERS | S14: MSP | T14: LIMITED | U14: =IF(ISNUMBER(SEARCH("ADD-ON",$I14)),"ADD-ON","NOT AN ADD-ON") -> NOT AN ADD-ON | V14: =CONCATENATE(R14,S14,T14,U14) -> MANAGED SERVICE PROVIDERSMSPLIMITEDNOT AN ADD-ON
A15: Enterprise Asset Management | B15: MAXIMO | C15: MXS EAM | D15: 5724U18 | E15: IBM Maximo Asset Management | F15: Maximo Asset Management | G15: 3570 | H15: D04XWLL | I15: IBM MAXIMO ASSET MANAGEMENT MANAGED SERVICE PROVIDERS AUTHORIZED USER LICENSE + SW SUBSCRIPTION & SUPPORT 12 MONTHS | J15: D04XWLL | K15: Authorized User | L15: 5 | M15: =ROUND(IF(K15="Authorized User",L15/3,L15),2) -> 1.67 | N15: 15 | O15: 5 | P15: 3570 | Q15: License + S&S | R15: MANAGED SERVICE PROVIDERS | S15: MSP | T15: AUTHORIZED | U15: =IF(ISNUMBER(SEARCH("ADD-ON",$I15)),"ADD-ON","NOT AN ADD-ON") -> NOT AN ADD-ON | V15: =CONCATENATE(R15,S15,T15,U15) -> MANAGED SERVICE PROVIDERSMSPAUTHORIZEDNOT AN ADD-ON
A16: Enterprise Asset Management | B16: MAXIMO | C16: MXS EAM | D16: 5724U18 | E16: IBM Maximo Asset Management | F16: Maximo Asset Management | G16: 2140 | H16: D04XXLL | I16: IBM MAXIMO ASSET MANAGEMENT MANAGED SERVICE PROVIDERS AUTHORIZED USER SW SUBSCRIPTION & SUPPORT REINSTATEMENT 12 MONTHS | J16: D04XWLL | K16: Authorized User | L16: 5 | M16: =ROUND(IF(K16="Authorized User",L16/3,L16),2) -> 1.67 | N16: 15 | O16: 5 | P16: 3570 | Q16: Reinstatement | R16: MANAGED SERVICE PROVIDERS | S16: MSP | T16: AUTHORIZED | U16: =IF(ISNUMBER(SEARCH("ADD-ON",$I16)),"ADD-ON","NOT AN ADD-ON") -> NOT AN ADD-ON | V16: =CONCATENATE(R16,S16,T16,U16) -> MANAGED SERVICE PROVIDERSMSPAUTHORIZEDNOT AN ADD-ON
... A26: Enterprise Asset Management | B26: MAXIMO | C26: MXS EAM | D26: 5724U18 | E26: IBM Maximo Asset Management | F26: Maximo Asset Management | G26: 1070 | H26: D06FVLL | I26: IBM MAXIMO ASSET MANAGEMENT MANAGED SERVICE PROVIDERS LIMITED USE FOR LINUX ON SYSTEM Z AUTHORIZED USER SW SUBSCRIPTION & SUPPORT REINSTATEMENT 12 MONTHS | J26: D06FULL | K26: Authorized User | L26: 0 | M26: =ROUND(IF(K26="Authorized User",L26/3,L26),2) -> 0 | N26: 5 | O26: 1.6666667 | P26: 1780 | Q26: Reinstatement | R26: MANAGED SERVICE PROVIDERS | S26: MSP | T26: LIMITED | U26: =IF(ISNUMBER(SEARCH("ADD-ON",$I26)),"ADD-ON","NOT AN ADD-ON") -> NOT AN ADD-ON | V26: =CONCATENATE(R26,S26,T26,U26) -> MANAGED SERVICE PROVIDERSMSPLIMITEDNOT AN ADD-ON
